<?xml version="1.0" encoding="UTF-8"?>
<!-- Generated by org.testng.reporters.JUnitReportReporter -->
<testsuite hostname="DESKTOP-5VR39KC" failures="1" tests="3" name="package1.ErrorValidation" time="27.617" errors="0" timestamp="2025-10-24T23:25:17 IST" skipped="1">
  <testcase classname="package1.ErrorValidation" name="LoginErrorValidation" time="6.428">
    <skipped/>
  </testcase> <!-- LoginErrorValidation -->
  <testcase classname="package1.ErrorValidation" name="ProductErrorValidation" time="11.044"/>
  <testcase classname="package1.ErrorValidation" name="LoginErrorValidation" time="10.145">
    <failure message="expected [Login Successfully] but found [Incorrect email or password]" type="java.lang.AssertionError">
      <![CDATA[java.lang.AssertionError: expected [Login Successfully] but found [Incorrect email or password]
at org.testng.Assert.fail(Assert.java:111)
at org.testng.Assert.failNotEquals(Assert.java:1578)
at org.testng.Assert.assertEqualsImpl(Assert.java:150)
at org.testng.Assert.assertEquals(Assert.java:132)
at org.testng.Assert.assertEquals(Assert.java:656)
at org.testng.Assert.assertEquals(Assert.java:666)
at package1.ErrorValidation.LoginErrorValidation(ErrorValidation.java:29)
at java.base/jdk.internal.reflect.DirectMethodHandleAccessor.invoke(DirectMethodHandleAccessor.java:104)
at java.base/java.lang.reflect.Method.invoke(Method.java:565)
at org.testng.internal.invokers.MethodInvocationHelper.invokeMethod(MethodInvocationHelper.java:141)
at org.testng.internal.invokers.TestInvoker.invokeMethod(TestInvoker.java:686)
at org.testng.internal.invokers.TestInvoker.retryFailed(TestInvoker.java:269)
at org.testng.internal.invokers.MethodRunner.runInSequence(MethodRunner.java:76)
at org.testng.internal.invokers.TestInvoker$MethodInvocationAgent.invoke(TestInvoker.java:992)
at org.testng.internal.invokers.TestInvoker.invokeTestMethods(TestInvoker.java:203)
at org.testng.internal.invokers.TestMethodWorker.invokeTestMethods(TestMethodWorker.java:154)
at org.testng.internal.invokers.TestMethodWorker.run(TestMethodWorker.java:134)
at java.base/java.util.ArrayList.forEach(ArrayList.java:1604)
at org.testng.TestRunner.privateRun(TestRunner.java:739)
at org.testng.TestRunner.run(TestRunner.java:614)
at org.testng.SuiteRunner.runTest(SuiteRunner.java:421)
at org.testng.SuiteRunner$SuiteWorker.run(SuiteRunner.java:463)
at org.testng.internal.thread.ThreadUtil.lambda$execute$0(ThreadUtil.java:64)
at java.base/java.util.concurrent.FutureTask.run(FutureTask.java:328)
at java.base/java.util.concurrent.ThreadPoolExecutor.runWorker(ThreadPoolExecutor.java:1090)
at java.base/java.util.concurrent.ThreadPoolExecutor$Worker.run(ThreadPoolExecutor.java:614)
at java.base/java.lang.Thread.run(Thread.java:1474)
]]>
    </failure>
  </testcase> <!-- LoginErrorValidation -->
</testsuite> <!-- package1.ErrorValidation -->
